Workbook

Sheet Inputs
B1: BioFresh SAS
B2: All amt are in €k
B4: HISTORICAL ANCHOR VALUES
B5: Revenue FY2024 | C5: 44600
B6: Revenue CAGR (FY22-FY24) | C6: 0.082
B7: Revenue FY2023 | C7: =ROUND(C5/1.082,0)
B8: Revenue FY2022 | C8: =ROUND(C7/1.082,0)
B9: Net Financial Debt FY2024 | C9: 3200
B11: HISTORICAL RATIOS
B12: Gross Margin | C12: 0.285
B13: SG&A % of Revenue | C13: 0.145
B14: EBITDA Margin FY2024 | C14: 0.14
B15: D&A % of Revenue | C15: 0.03
B16: Interest Coverage | C16: 11.5
B17: Implied Interest Expense FY2024 | C17: =ROUND(C5*C14/C16,0)
B18: Tax Rate | C18: 0.25
B20: PROJECTION PARAMETERS
B21: D&A % (all years) | C21: 0.03
B22: Capex % (all years) | C22: 0.025
B23: NWC % (all years) | C23: 0.08
B24: Terminal Growth Rate | C24: 0.025
B26: SCENARIOS
B27: BEAR - Revenue Growth | C27: 0.03
B28: BEAR - EBITDA Margin (all years) | C28: 0.13
B29: BASE - Revenue Growth | C29: 0.08
B30: BASE - EBITDA Margin Yr1 | C30: 0.145
B31: BASE - EBITDA Margin Yr2-5 | C31: 0.15
B32: BULL - Revenue Growth | C32: 0.12
B33: BULL - EBITDA Margin (all years) | C33: 0.155
B35: LBO STRUCTURE
B36: Entry EV | C36: 75000
B37: Equity % | C37: 0.4
B38: Equity Invested | C38: =C36*C37
B39: Senior Debt | C39: =C36*(1-C37)
B40: LBO Interest Rate | C40: 0.07
B41: Annual Amortization | C41: 5000
B42: Exit Multiple | C42: 12
B44: WACC INPUTS
B45: Risk-Free Rate (10Y OAT) | C45: 0.033
B46: Equity Beta | C46: 0.85
...

Sheet P&L
B1: INCOME STATEMENT + FCF BRIDGE
C4: FY2022 | D4: FY2023 | E4: FY2024 | F4: FY2025E | G4: FY2026E | H4: FY2027E | I4: FY2028E | J4: FY2029E
B5: Revenue | C5: =Inputs!$C$8 | D5: =Inputs!$C$7 | E5: =Inputs!$C$5 | F5: =E5*(1+Inputs!$C$29) | G5: =F5*(1+Inputs!$C$29) | H5: =G5*(1+Inputs!$C$29) | I5: =H5*(1+Inputs!$C$29) | J5: =I5*(1+Inputs!$C$29)
B6: Revenue Growth | D6: =D5/C5-1 | E6: =E5/D5-1 | F6: =Inputs!$C$29 | G6: =Inputs!$C$29 | H6: =Inputs!$C$29 | I6: =Inputs!$C$29 | J6: =Inputs!$C$29
B8: Gross Profit | C8: =ROUND(C5*Inputs!$C$12,0) | D8: =ROUND(D5*Inputs!$C$12,0) | E8: =ROUND(E5*Inputs!$C$12,0) | F8: =ROUND(F5*Inputs!$C$12,0) | G8: =ROUND(G5*Inputs!$C$12,0) | H8: =ROUND(H5*Inputs!$C$12,0) | I8: =ROUND(I5*Inputs!$C$12,0) | J8: =ROUND(J5*Inputs!$C$12,0)
B9: SG&A | C9: =ROUND(-C5*Inputs!$C$13,0) | D9: =ROUND(-D5*Inputs!$C$13,0) | E9: =ROUND(-E5*Inputs!$C$13,0) | F9: =ROUND(-F5*Inputs!$C$13,0) | G9: =ROUND(-G5*Inputs!$C$13,0) | H9: =ROUND(-H5*Inputs!$C$13,0) | I9: =ROUND(-I5*Inputs!$C$13,0) | J9: =ROUND(-J5*Inputs!$C$13,0)
B10: EBITDA | C10: =C8+C9 | D10: =D8+D9 | E10: =E8+E9 | F10: =F5*Inputs!$C$30 | G10: =G5*Inputs!$C$31 | H10: =H5*Inputs!$C$31 | I10: =I5*Inputs!$C$31 | J10: =J5*Inputs!$C$31
B11: EBITDA Margin | C11: =C10/C5 | D11: =D10/D5 | E11: =E10/E5 | F11: =F10/F5 | G11: =G10/G5 | H11: =H10/H5 | I11: =I10/I5 | J11: =J10/J5
B13: D&A | C13: =ROUND(-C5*Inputs!$C$21,0) | D13: =ROUND(-D5*Inputs!$C$21,0) | E13: =ROUND(-E5*Inputs!$C$21,0) | F13: =ROUND(-F5*Inputs!$C$21,0) | G13: =ROUND(-G5*Inputs!$C$21,0) | H13: =ROUND(-H5*Inputs!$C$21,0) | I13: =ROUND(-I5*Inputs!$C$21,0) | J13: =ROUND(-J5*Inputs!$C$21,0)
B14: EBIT | C14: =C10+C13 | D14: =D10+D13 | E14: =E10+E13 | F14: =F10+F13 | G14: =G10+G13 | H14: =H10+H13 | I14: =I10+I13 | J14: =J10+J13
B15: Tax | C15: =ROUND(-MAX(0,C14)*Inputs!$C$18,0) | D15: =ROUND(-MAX(0,D14)*Inputs!$C$18,0) | E15: =ROUND(-MAX(0,E14)*Inputs!$C$18,0) | F15: =ROUND(-MAX(0,F14)*Inputs!$C$18,0) | G15: =ROUND(-MAX(0,G14)*Inputs!$C$18,0) | H15: =ROUND(-MAX(0,H14)*Inputs!$C$18,0) | I15: =ROUND(-MAX(0,I14)*Inputs!$C$18,0) | J15: =ROUND(-MAX(0,J14)*Inputs!$C$18,0)
B16: NOPAT | C16: =C14+C15 | D16: =D14+D15 | E16: =E14+E15 | F16: =F14+F15 | G16: =G14+G15 | H16: =H14+H15 | I16: =I14+I15 | J16: =J14+J15
B18: FREE CASH FLOW BRIDGE (Unlevered)
C19: FY2022 | D19: FY2023 | E19: FY2024 | F19: FY2025E | G19: FY2026E | H19: FY2027E | I19: FY2028E | J19: FY2029E
B20: Add back D&A | C20: =-C13 | D20: =-D13 | E20: =-E13 | F20: =-F13 | G20: =-G13 | H20: =-H13 | I20: =-I13 | J20: =-J13
B21: Less: Capex | C21: =ROUND(-C5*Inputs!$C$22,0) | D21: =ROUND(-D5*Inputs!$C$22,0) | E21: =ROUND(-E5*Inputs!$C$22,0) | F21: =ROUND(-F5*Inputs!$C$22,0) | G21: =ROUND(-G5*Inputs!$C$22,0) | H21: =ROUND(-H5*Inputs!$C$22,0) | I21: =ROUND(-I5*Inputs!$C$22,0) | J21: =ROUND(-J5*Inputs!$C$22,0)
B22: Less: Change in NWC | D22: =ROUND(-(D5-C5)*Inputs!$C$23,0) | E22: =ROUND(-(E5-D5)*Inputs!$C$23,0) | F22: =ROUND(-(F5-E5)*Inputs!$C$23,0) | G22: =ROUND(-(G5-F5)*Inputs!$C$23,0) | H22: =ROUND(-(H5-G5)*Inputs!$C$23,0) | I22: =ROUND(-(I5-H5)*Inputs!$C$23,0) | J22: =ROUND(-(J5-I5)*Inputs!$C$23,0)
B23: UNLEVERED FREE CASH FLOW | D23: =SUM(D16:D22) | E23: =SUM(E16:E22) | F23: =SUM(F16:F22) | G23: =SUM(G16:G22) | H23: =SUM(H16:H22) | I23: =SUM(I16:I22) | J23: =SUM(J16:J22)

Sheet WACC
B1: WACC CALCULATION - BioFresh SAS
B3: STEP 1 - Cost of Equity (CAPM)
B4: Risk-Free Rate | C4: =Inputs!$C$45 | D4: 10Y OAT - Banque de France
B5: Equity Beta | C5: =Inputs!$C$46 | D5: Damodaran
B6: Equity Risk Premium (ERP) | C6: =Inputs!$C$47 | D6: Damodaran
B7: Cost of Equity | C7: =C4+C5*C6
B9: STEP 2 - After-Tax Cost of Debt
B10: Pre-Tax Cost of Debt | C10: =Inputs!$C$48
B11: Tax Rate | C11: =Inputs!$C$18
B12: After-Tax Cost of Debt | C12: =C10*(1-C11)
B14: STEP 3 - WACC
B15: Equity Weight (We) | C15: =Inputs!$C$50
B16: Debt Weight (Wd) | C16: =Inputs!$C$49
B17: WACC | C17: =C15*C7+C16*C12

Sheet DCF
B1: DCF VALUATION - BioFresh SAS
C4: FY2025E | D4: FY2026E | E4: FY2027E | F4: FY2028E | G4: FY2029E
B5: Unlevered FCF | C5: ='P&L'!F23 | D5: ='P&L'!G23 | E5: ='P&L'!H23 | F5: ='P&L'!I23 | G5: ='P&L'!J23
B6: PV Factor | C6: =1/(1+WACC!$C$17)^1 | D6: =1/(1+WACC!$C$17)^2 | E6: =1/(1+WACC!$C$17)^3 | F6: =1/(1+WACC!$C$17)^4 | G6: =1/(1+WACC!$C$17)^5
B7: PV of FCF | C7: =C5*C6 | D7: =D5*D6 | E7: =E5*E6 | F7: =F5*F6 | G7: =G5*G6
B9: ENTERPRISE VALUE BRIDGE (BASE CASE)
B10: Sum of PV(FCF) | C10: =SUM(C7:G7)
B11: Terminal FCF (FY2030E) | C11: =G5*(1+Inputs!$C$24)
B12: Terminal Value (Gordon Growth) | C12: =C11/(WACC!$C$17-Inputs!$C$24)
B13: PV of Terminal Value | C13: =C12*G6
B15: ENTERPRISE VALUE (DCF) | C15: =C10+C13
B16: Less: Net Financial Debt | C16: =-Inputs!$C$9
B17: EQUITY VALUE (DCF) | C17: =C15+C16
B19: NPV OF ACQUISITION (All Three Scenarios)
B20: Particular | C20: BEAR | D20: BASE | E20: BULL
B21: DCF Enterprise Value | C21: =Scenarios!$C$22 | D21: =Scenarios!$C$52 | E21: =Scenarios!$C$82
B22: Less: Entry EV | C22: =-Inputs!$C$36 | D22: =-Inputs!$C$36 | E22: =-Inputs!$C$36
B23: NPV of Acquisition | C23: =Scenarios!$C$23 | D23: =Scenarios!$C$53 | E23: =Scenarios!$C$83
B24: DCF Implied EV/EBITDA | C24: =ROUND(Scenarios!$C$22/(Inputs!$C$5*(1+Inputs!$C$27)^5*Inputs!$C$28),1) | D24: =ROUND(Scenarios!$C$52/('P&L'!J10),1) | E24: =ROUND(Scenarios!$C$82/(Inputs!$C$5*(1+Inputs!$C$32)^5*Inputs!$C$33),1)
B25: LBO IRR (Yr 5 exit at 12x) | C25: =Scenarios!$C$32 | D25: =Scenarios!$C$62 | E25: =Scenarios!$C$92
B26: LBO MOIC | C26: =Scenarios!$C$31 | D26: =Scenarios!$C$61 | E26: =Scenarios!$C$91

Sheet Scenarios
B1: SCENARIO ANALYSIS
B4: BEAR SCENARIO - Growth 3% p.a. | EBITDA Margin 13.0%
C5: FY2025E | D5: FY2026E | E5: FY2027E | F5: FY2028E | G5: FY2029E
B6: Revenue | C6: =ROUND(Inputs!$C$5*(1+Inputs!$C$27)^1,0) | D6: =ROUND(Inputs!$C$5*(1+Inputs!$C$27)^2,0) | E6: =ROUND(Inputs!$C$5*(1+Inputs!$C$27)^3,0) | F6: =ROUND(Inputs!$C$5*(1+Inputs!$C$27)^4,0) | G6: =ROUND(Inputs!$C$5*(1+Inputs!$C$27)^5,0)
B7: EBITDA | C7: =ROUND(C6*Inputs!$C$28,0+I10) | D7: =ROUND(D6*Inputs!$C$28,0) | E7: =ROUND(E6*Inputs!$C$28,0) | F7: =ROUND(F6*Inputs!$C$28,0) | G7: =ROUND(G6*Inputs!$C$28,0)
B8: D&A | C8: =ROUND(C6*Inputs!$C$21,0) | D8: =ROUND(D6*Inputs!$C$21,0) | E8: =ROUND(E6*Inputs!$C$21,0) | F8: =ROUND(F6*Inputs!$C$21,0) | G8: =ROUND(G6*Inputs!$C$21,0)
B9: EBIT | C9: =C7-C8 | D9: =D7-D8 | E9: =E7-E8 | F9: =F7-F8 | G9: =G7-G8
B10: NOPAT | C10: =ROUND(C9*(1-Inputs!$C$18),0) | D10: =ROUND(D9*(1-Inputs!$C$18),0) | E10: =ROUND(E9*(1-Inputs!$C$18),0) | F10: =ROUND(F9*(1-Inputs!$C$18),0) | G10: =ROUND(G9*(1-Inputs!$C$18),0)
B11: Less: Capex | C11: =ROUND(C6*Inputs!$C$22,0) | D11: =ROUND(D6*Inputs!$C$22,0) | E11: =ROUND(E6*Inputs!$C$22,0) | F11: =ROUND(F6*Inputs!$C$22,0) | G11: =ROUND(G6*Inputs!$C$22,0)
B12: Less: Increase in NWC | C12: =ROUND((C6-Inputs!$C$5)*Inputs!$C$23,0) | D12: =ROUND((D6-Inputs!$C$5*(1+Inputs!$C$27)^1)*Inputs!$C$23,0) | E12: =ROUND((E6-Inputs!$C$5*(1+Inputs!$C$27)^2)*Inputs!$C$23,0) | F12: =ROUND((F6-Inputs!$C$5*(1+Inputs!$C$27)^3)*Inputs!$C$23,0) | G12: =ROUND((G6-Inputs!$C$5*(1+Inputs!$C$27)^4)*Inputs!$C$23,0)
B13: UNLEVERED FREE CASH FLOW | C13: =C10+C8-C11-C12 | D13: =D10+D8-D11-D12 | E13: =E10+E8-E11-E12 | F13: =F10+F8-F11-F12 | G13: =G10+G8-G11-G12
B14: PV Factor | C14: =1/(1+WACC!$C$17)^1 | D14: =1/(1+WACC!$C$17)^2 | E14: =1/(1+WACC!$C$17)^3 | F14: =1/(1+WACC!$C$17)^4 | G14: =1/(1+WACC!$C$17)^5
B15: PV of UFCF | C15: =ROUND(C13*C14,0) | D15: =ROUND(D13*D14,0) | E15: =ROUND(E13*E14,0) | F15: =ROUND(F13*F14,0) | G15: =ROUND(G13*G14,0)
B17: BEAR
B18: Sum of PV | C18: =SUM(C15:G15)
B19: Terminal FCF | C19: =G13*(1+Inputs!$C$24)
B20: Terminal Value (Gordon Growth) | C20: =C19/(WACC!$C$17-Inputs!$C$24)
B21: PV of Terminal Value | C21: =ROUND(C20*G14,0)
B22: DCF ENTERPRISE VALUE | C22: =C18+C21
B23: NPV OF ACQUISITION | C23: =C22-Inputs!$C$36
B25: BEAR - LBO RETURNS
B26: Exit EBITDA | C26: =G7
B27: Exit EV | C27: =C26*Inputs!$C$42
B28: Remaining Debt | C28: =Inputs!$C$39-5*Inputs!$C$41
B29: Exit Equity Value | C29: =C27-C28
B30: Equity Invested | C30: =Inputs!$C$38
B31: MOIC | C31: =C29/C30
B32: IRR (Exit Year 5) | C32: =(C29/C30)^(1/5)-1
B34: BASE SCENARIO - Growth 8% p.a. | EBITDA Margin 14.5%
C35: FY2025E | D35: FY2026E | E35: FY2027E | F35: FY2028E | G35: FY2029E
B36: Revenue | C36: =ROUND(Inputs!$C$5*(1+Inputs!$C$29)^1,0) | D36: =ROUND(Inputs!$C$5*(1+Inputs!$C$29)^2,0) | E36: =ROUND(Inputs!$C$5*(1+Inputs!$C$29)^3,0) | F36: =ROUND(Inputs!$C$5*(1+Inputs!$C$29)^4,0) | G36: =ROUND(Inputs!$C$5*(1+Inputs!$C$29)^5,0)
B37: EBITDA | C37: =ROUND(C36*Inputs!$C$30,0) | D37: =ROUND(D36*Inputs!$C$31,0) | E37: =ROUND(E36*Inputs!$C$31,0) | F37: =ROUND(F36*Inputs!$C$31,0) | G37: =ROUND(G36*Inputs!$C$31,0)
B38: D&A | C38: =ROUND(C36*Inputs!$C$21,0) | D38: =ROUND(D36*Inputs!$C$21,0) | E38: =ROUND(E36*Inputs!$C$21,0) | F38: =ROUND(F36*Inputs!$C$21,0) | G38: =ROUND(G36*Inputs!$C$21,0)
B39: EBIT | C39: =C37-C38 | D39: =D37-D38 | E39: =E37-E38 | F39: =F37-F38 | G39: =G37-G38
B40: NOPAT | C40: =ROUND(C39*(1-Inputs!$C$18),0) | D40: =ROUND(D39*(1-Inputs!$C$18),0) | E40: =ROUND(E39*(1-Inputs!$C$18),0) | F40: =ROUND(F39*(1-Inputs!$C$18),0) | G40: =ROUND(G39*(1-Inputs!$C$18),0)
B41: Less: Capex | C41: =ROUND(C36*Inputs!$C$22,0) | D41: =ROUND(D36*Inputs!$C$22,0) | E41: =ROUND(E36*Inputs!$C$22,0) | F41: =ROUND(F36*Inputs!$C$22,0) | G41: =ROUND(G36*Inputs!$C$22,0)
B42: Less: Increase in NWC | C42: =ROUND((C36-Inputs!$C$5)*Inputs!$C$23,0) | D42: =ROUND((D36-Inputs!$C$5*(1+Inputs!$C$29)^1)*Inputs!$C$23,0) | E42: =ROUND((E36-Inputs!$C$5*(1+Inputs!$C$29)^2)*Inputs!$C$23,0) | F42: =ROUND((F36-Inputs!$C$5*(1+Inputs!$C$29)^3)*Inputs!$C$23,0) | G42: =ROUND((G36-Inputs!$C$5*(1+Inputs!$C$29)^4)*Inputs!$C$23,0)
B43: UNLEVERED FREE CASH FLOW | C43: =C40+C38-C41-C42 | D43: =D40+D38-D41-D42 | E43: =E40+E38-E41-E42 | F43: =F40+F38-F41-F42 | G43: =G40+G38-G41-G42
B44: PV Factor | C44: =1/(1+WACC!$C$17)^1 | D44: =1/(1+WACC!$C$17)^2 | E44: =1/(1+WACC!$C$17)^3 | F44: =1/(1+WACC!$C$17)^4 | G44: =1/(1+WACC!$C$17)^5
B45: PV of UFCF | C45: =ROUND(C43*C44,0) | D45: =ROUND(D43*D44,0) | E45: =ROUND(E43*E44,0) | F45: =ROUND(F43*F44,0) | G45: =ROUND(G43*G44,0)
...

Sheet LBO
B1: LBO MODEL - BioFresh SAS
B3: SOURCES & USES
B4: USES | E4: SOURCES
B5: Purchase Price | C5: =Inputs!$C$36 | E5: Equity (40%) | F5: =Inputs!$C$38
B6: Advisory Fees (2%) | C6: =Inputs!$C$36*0.02 | E6: Senior Debt (60%) | F6: =Inputs!$C$39
B7: TOTAL USES | C7: =C5+C6 | E7: TOTAL SOURCES | F7: =F5+F6
B9: DEBT SCHEDULE (Senior Secured)
C10: FY2024 | D10: FY2025 | E10: FY2026 | F10: FY2027 | G10: FY2028 | H10: FY2029
B11: Beginning Debt Balance | C11: =Inputs!$C$39 | D11: =C14 | E11: =D14 | F11: =E14 | G11: =F14 | H11: =G14
B12: Interest Expense | C12: =-C11*Inputs!$C$40 | D12: =-D11*Inputs!$C$40 | E12: =-E11*Inputs!$C$40 | F12: =-F11*Inputs!$C$40 | G12: =-G11*Inputs!$C$40 | H12: =-H11*Inputs!$C$40
B13: Principal Repayment | D13: =-Inputs!$C$41 | E13: =-Inputs!$C$41 | F13: =-Inputs!$C$41 | G13: =-Inputs!$C$41 | H13: =-Inputs!$C$41
B14: Ending Debt Balance | C14: =C11 | D14: =C14+D13 | E14: =D14+E13 | F14: =E14+F13 | G14: =F14+G13 | H14: =G14+H13
B16: CREDIT STATISTICS (Base Case EBITDA)
C17: FY2024
D18: FY2025
E19: FY2026
F20: FY2027
G21: FY2028
H22: FY2029
B23: EBITDA | C23: ='P&L'!E10 | D23: ='P&L'!F10 | E23: ='P&L'!G10 | F23: ='P&L'!H10 | G23: ='P&L'!I10 | H23: ='P&L'!J10
B24: Debt / EBITDA | C24: =C14/C23 | D24: =D14/D23 | E24: =E14/E23 | F24: =F14/F23 | G24: =G14/G23 | H24: =H14/H23
B25: Interest Coverage | D25: =D23/-D12 | E25: =E23/-E12 | F25: =F23/-F12 | G25: =G23/-G12 | H25: =H23/-H12
B27: EXIT ANALYSIS & RETURNS (Base Case)
B28: Exit EBITDA | C28: ='P&L'!J10
B29: Exit EV/EBITDA Multiple | C29: =Inputs!$C$42
B30: Exit Enterprise Value | C30: =C28*C29
B31: Less: Remaining Debt | C31: =-H14
B32: Exit Equity Value | C32: =C30+C31
B34: Equity Invested | C34: =Inputs!$C$38
B35: MOIC | C35: =C32/C34
B37: Equity Cash Flows for IRR | C37: Yr 0 | D37: Yr 1 | E37: Yr 2 | F37: Yr 3 | G37: Yr 4 | H37: Yr 5
C38: =-C34 | D38: 0 | E38: 0 | F38: 0 | G38: 0 | H38: =C32
B39: IRR (Base Case) | C39: =IRR(C38:H38)

Sheet Sensitivity
B1: NPV SENSITIVITY
B4: Wacc / Revenue growth | C4: 0 | D4: 0.03 | E4: 0.05 | F4: 0.08 | G4: 0.1 | H4: 0.12 | I4: 0.15
B5: 0.05 | C5: =ROUND(Inputs!$C$5*(1+C$4)^1*(Inputs!$C$30*(1-Inputs!$C$18)+Inputs!$C$21*Inputs!$C$18-Inputs!$C$22-C$4/(1+C$4)*Inputs!$C$23)/(1+$B$5)^1+Inputs!$C$5*(1+C$4)^2*(Inputs!$C$31*(1-Inputs!$C$18)+Inputs!$C$21*Inputs!$C$18-Inputs!$C$22-C$4/(1+C$4)*Inputs!$C$23)/(1+$B$5)^2+Inputs!$C$5*(1+C$4)^3*(Inputs!$C$31*(1-Inputs!$C$18)+Inputs!$C$21*Inputs!$C$18-Inputs!$C$22-C$4/(1+C$4)*Inputs!$C$23)/(1+$B$5)^3+Inputs!$C$5*(1+C$4)^4*(Inputs!$C$31*(1-Inputs!$C$18)+Inputs!$C$21*Inputs!$C$18-Inputs!$C$22-C$4/(1+C$4)*Inputs!$C$23)/(1+$B$5)^4+Inputs!$C$5*(1+C$4)^5*(Inputs!$C$31*(1-Inputs!$C$18)+Inputs!$C$21*Inputs!$C$18-Inputs!$C$22-C$4/(1+C$4)*Inputs!$C$23)/(1+$B$5)^5+Inputs!$C$5*(1+C$4)^5*(Inputs!$C$31*(1-Inputs!$C$18)+Inputs!$C$21*Inputs!$C$18-Inputs!$C$22-C$4/(1+C$4)*Inputs!$C$23)*(1+Inputs!$C$24)/($B$5-Inputs!$C$24)/(1+$B$5)^5-Inputs!$C$36,0) | D5: =ROUND(Inputs!$C$5*(1+D$4)^1*(Inputs!$C$30*(1-Inputs!$C$18)+Inputs!$C$21*Inputs!$C$18-Inputs!$C$22-D$4/(1+D$4)*Inputs!$C$23)/(1+$B$5)^1+Inputs!$C$5*(1+D$4)^2*(Inputs!$C$31*(1-Inputs!$C$18)+Inputs!$C$21*Inputs!$C$18-Inputs!$C$22-D$4/(1+D$4)*Inputs!$C$23)/(1+$B$5)^2+Inputs!$C$5*(1+D$4)^3*(Inputs!$C$31*(1-Inputs!$C$18)+Inputs!$C$21*Inputs!$C$18-Inputs!$C$22-D$4/(1+D$4)*Inputs!$C$23)/(1+$B$5)^3+Inputs!$C$5*(1+D$4)^4*(Inputs!$C$31*(1-Inputs!$C$18)+Inputs!$C$21*Inputs!$C$18-Inputs!$C$22-D$4/(1+D$4)*Inputs!$C$23)/(1+$B$5)^4+Inputs!$C$5*(1+D$4)^5*(Inputs!$C$31*(1-Inputs!$C$18)+Inputs!$C$21*Inputs!$C$18-Inputs!$C$22-D$4/(1+D$4)*Inputs!$C$23)/(1+$B$5)^5+Inputs!$C$5*(1+D$4)^5*(Inputs!$C$31*(1-Inputs!$C$18)+Inputs!$C$21*Inputs!$C$18-Inputs!$C$22-D$4/(1+D$4)*Inputs!$C$23)*(1+Inputs!$C$24)/($B$5-Inputs!$C$24)/(1+$B$5)^5-Inputs!$C$36,0) | E5: =ROUND(Inputs!$C$5*(1+E$4)^1*(Inputs!$C$30*(1-Inputs!$C$18)+Inputs!$C$21*Inputs!$C$18-Inputs!$C$22-E$4/(1+E$4)*Inputs!$C$23)/(1+$B$5)^1+Inputs!$C$5*(1+E$4)^2*(Inputs!$C$31*(1-Inputs!$C$18)+Inputs!$C$21*Inputs!$C$18-Inputs!$C$22-E$4/(1+E$4)*Inputs!$C$23)/(1+$B$5)^2+Inputs!$C$5*(1+E$4)^3*(Inputs!$C$31*(1-Inputs!$C$18)+Inputs!$C$21*Inputs!$C$18-Inputs!$C$22-E$4/(1+E$4)*Inputs!$C$23)/(1+$B$5)^3+Inputs!$C$5*(1+E$4)^4*(Inputs!$C$31*(1-Inputs!$C$18)+Inputs!$C$21*Inputs!$C$18-Inputs!$C$22-E$4/(1+E$4)*Inputs!$C$23)/(1+$B$5)^4+Inputs!$C$5*(1+E$4)^5*(Inputs!$C$31*(1-Inputs!$C$18)+Inputs!$C$21*Inputs!$C$18-Inputs!$C$22-E$4/(1+E$4)*Inputs!$C$23)/(1+$B$5)^5+Inputs!$C$5*(1+E$4)^5*(Inputs!$C$31*(1-Inputs!$C$18)+Inputs!$C$21*Inputs!$C$18-Inputs!$C$22-E$4/(1+E$4)*Inputs!$C$23)*(1+Inputs!$C$24)/($B$5-Inputs!$C$24)/(1+$B$5)^5-Inputs!$C$36,0) | F5: =ROUND(Inputs!$C$5*(1+F$4)^1*(Inputs!$C$30*(1-Inputs!$C$18)+Inputs!$C$21*Inputs!$C$18-Inputs!$C$22-F$4/(1+F$4)*Inputs!$C$23)/(1+$B$5)^1+Inputs!$C$5*(1+F$4)^2*(Inputs!$C$31*(1-Inputs!$C$18)+Inputs!$C$21*Inputs!$C$18-Inputs!$C$22-F$4/(1+F$4)*Inputs!$C$23)/(1+$B$5)^2+Inputs!$C$5*(1+F$4)^3*(Inputs!$C$31*(1-Inputs!$C$18)+Inputs!$C$21*Inputs!$C$18-Inputs!$C$22-F$4/(1+F$4)*Inputs!$C$23)/(1+$B$5)^3+Inputs!$C$5*(1+F$4)^4*(Inputs!$C$31*(1-Inputs!$C$18)+Inputs!$C$21*Inputs!$C$18-Inputs!$C$22-F$4/(1+F$4)*Inputs!$C$23)/(1+$B$5)^4+Inputs!$C$5*(1+F$4)^5*(Inputs!$C$31*(1-Inputs!$C$18)+Inputs!$C$21*Inputs!$C$18-Inputs!$C$22-F$4/(1+F$4)*Inputs!$C$23)/(1+$B$5)^5+Inputs!$C$5*(1+F$4)^5*(Inputs!$C$31*(1-Inputs!$C$18)+Inputs!$C$21*Inputs!$C$18-Inputs!$C$22-F$4/(1+F$4)*Inputs!$C$23)*(1+Inputs!$C$24)/($B$5-Inputs!$C$24)/(1+$B$5)^5-Inputs!$C$36,0) | G5: =ROUND(Inputs!$C$5*(1+G$4)^1*(Inputs!$C$30*(1-Inputs!$C$18)+Inputs!$C$21*Inputs!$C$18-Inputs!$C$22-G$4/(1+G$4)*Inputs!$C$23)/(1+$B$5)^1+Inputs!$C$5*(1+G$4)^2*(Inputs!$C$31*(1-Inputs!$C$18)+Inputs!$C$21*Inputs!$C$18-Inputs!$C$22-G$4/(1+G$4)*Inputs!$C$23)/(1+$B$5)^2+Inputs!$C$5*(1+G$4)^3*(Inputs!$C$31*(1-Inputs!$C$18)+Inputs!$C$21*Inputs!$C$18-Inputs!$C$22-G$4/(1+G$4)*Inputs!$C$23)/(1+$B$5)^3+Inputs!$C$5*(1+G$4)^4*(Inputs!$C$31*(1-Inputs!$C$18)+Inputs!$C$21*Inputs!$C$18-Inputs!$C$22-G$4/(1+G$4)*Inputs!$C$23)/(1+$B$5)^4+Inputs!$C$5*(1+G$4)^5*(Inputs!$C$31*(1-Inputs!$C$18)+Inputs!$C$21*Inputs!$C$18-Inputs!$C$22-G$4/(1+G$4)*Inputs!$C$23)/(1+$B$5)^5+Inputs!$C$5*(1+G$4)^5*(Inputs!$C$31*(1-Inputs!$C$18)+Inputs!$C$21*Inputs!$C$18-Inputs!$C$22-G$4/(1+G$4)*Inputs!$C$23)*(1+Inputs!$C$24)/($B$5-Inputs!$C$24)/(1+$B$5)^5-Inputs!$C$36,0) | H5: =ROUND(Inputs!$C$5*(1+H$4)^1*(Inputs!$C$30*(1-Inputs!$C$18)+Inputs!$C$21*Inputs!$C$18-Inputs!$C$22-H$4/(1+H$4)*Inputs!$C$23)/(1+$B$5)^1+Inputs!$C$5*(1+H$4)^2*(Inputs!$C$31*(1-Inputs!$C$18)+Inputs!$C$21*Inputs!$C$18-Inputs!$C$22-H$4/(1+H$4)*Inputs!$C$23)/(1+$B$5)^2+Inputs!$C$5*(1+H$4)^3*(Inputs!$C$31*(1-Inputs!$C$18)+Inputs!$C$21*Inputs!$C$18-Inputs!$C$22-H$4/(1+H$4)*Inputs!$C$23)/(1+$B$5)^3+Inputs!$C$5*(1+H$4)^4*(Inputs!$C$31*(1-Inputs!$C$18)+Inputs!$C$21*Inputs!$C$18-Inputs!$C$22-H$4/(1+H$4)*Inputs!$C$23)/(1+$B$5)^4+Inputs!$C$5*(1+H$4)^5*(Inputs!$C$31*(1-Inputs!$C$18)+Inputs!$C$21*Inputs!$C$18-Inputs!$C$22-H$4/(1+H$4)*Inputs!$C$23)/(1+$B$5)^5+Inputs!$C$5*(1+H$4)^5*(Inputs!$C$31*(1-Inputs!$C$18)+Inputs!$C$21*Inputs!$C$18-Inputs!$C$22-H$4/(1+H$4)*Inputs!$C$23)*(1+Inputs!$C$24)/($B$5-Inputs!$C$24)/(1+$B$5)^5-Inputs!$C$36,0) | I5: =ROUND(Inputs!$C$5*(1+I$4)^1*(Inputs!$C$30*(1-Inputs!$C$18)+Inputs!$C$21*Inputs!$C$18-Inputs!$C$22-I$4/(1+I$4)*Inputs!$C$23)/(1+$B$5)^1+Inputs!$C$5*(1+I$4)^2*(Inputs!$C$31*(1-Inputs!$C$18)+Inputs!$C$21*Inputs!$C$18-Inputs!$C$22-I$4/(1+I$4)*Inputs!$C$23)/(1+$B$5)^2+Inputs!$C$5*(1+I$4)^3*(Inputs!$C$31*(1-Inputs!$C$18)+Inputs!$C$21*Inputs!$C$18-Inputs!$C$22-I$4/(1+I$4)*Inputs!$C$23)/(1+$B$5)^3+Inputs!$C$5*(1+I$4)^4*(Inputs!$C$31*(1-Inputs!$C$18)+Inputs!$C$21*Inputs!$C$18-Inputs!$C$22-I$4/(1+I$4)*Inputs!$C$23)/(1+$B$5)^4+Inputs!$C$5*(1+I$4)^5*(Inputs!$C$31*(1-Inputs!$C$18)+Inputs!$C$21*Inputs!$C$18-Inputs!$C$22-I$4/(1+I$4)*Inputs!$C$23)/(1+$B$5)^5+Inputs!$C$5*(1+I$4)^5*(Inputs!$C$31*(1-Inputs!$C$18)+Inputs!$C$21*Inputs!$C$18-Inputs!$C$22-I$4/(1+I$4)*Inputs!$C$23)*(1+Inputs!$C$24)/($B$5-Inputs!$C$24)/(1+$B$5)^5-Inputs!$C$36,0)
B6: 0.06 | C6: =ROUND(Inputs!$C$5*(1+C$4)^1*(Inputs!$C$30*(1-Inputs!$C$18)+Inputs!$C$21*Inputs!$C$18-Inputs!$C$22-C$4/(1+C$4)*Inputs!$C$23)/(1+$B$6)^1+Inputs!$C$5*(1+C$4)^2*(Inputs!$C$31*(1-Inputs!$C$18)+Inputs!$C$21*Inputs!$C$18-Inputs!$C$22-C$4/(1+C$4)*Inputs!$C$23)/(1+$B$6)^2+Inputs!$C$5*(1+C$4)^3*(Inputs!$C$31*(1-Inputs!$C$18)+Inputs!$C$21*Inputs!$C$18-Inputs!$C$22-C$4/(1+C$4)*Inputs!$C$23)/(1+$B$6)^3+Inputs!$C$5*(1+C$4)^4*(Inputs!$C$31*(1-Inputs!$C$18)+Inputs!$C$21*Inputs!$C$18-Inputs!$C$22-C$4/(1+C$4)*Inputs!$C$23)/(1+$B$6)^4+Inputs!$C$5*(1+C$4)^5*(Inputs!$C$31*(1-Inputs!$C$18)+Inputs!$C$21*Inputs!$C$18-Inputs!$C$22-C$4/(1+C$4)*Inputs!$C$23)/(1+$B$6)^5+Inputs!$C$5*(1+C$4)^5*(Inputs!$C$31*(1-Inputs!$C$18)+Inputs!$C$21*Inputs!$C$18-Inputs!$C$22-C$4/(1+C$4)*Inputs!$C$23)*(1+Inputs!$C$24)/($B$6-Inputs!$C$24)/(1+$B$6)^5-Inputs!$C$36,0) | D6: =ROUND(Inputs!$C$5*(1+D$4)^1*(Inputs!$C$30*(1-Inputs!$C$18)+Inputs!$C$21*Inputs!$C$18-Inputs!$C$22-D$4/(1+D$4)*Inputs!$C$23)/(1+$B$6)^1+Inputs!$C$5*(1+D$4)^2*(Inputs!$C$31*(1-Inputs!$C$18)+Inputs!$C$21*Inputs!$C$18-Inputs!$C$22-D$4/(1+D$4)*Inputs!$C$23)/(1+$B$6)^2+Inputs!$C$5*(1+D$4)^3*(Inputs!$C$31*(1-Inputs!$C$18)+Inputs!$C$21*Inputs!$C$18-Inputs!$C$22-D$4/(1+D$4)*Inputs!$C$23)/(1+$B$6)^3+Inputs!$C$5*(1+D$4)^4*(Inputs!$C$31*(1-Inputs!$C$18)+Inputs!$C$21*Inputs!$C$18-Inputs!$C$22-D$4/(1+D$4)*Inputs!$C$23)/(1+$B$6)^4+Inputs!$C$5*(1+D$4)^5*(Inputs!$C$31*(1-Inputs!$C$18)+Inputs!$C$21*Inputs!$C$18-Inputs!$C$22-D$4/(1+D$4)*Inputs!$C$23)/(1+$B$6)^5+Inputs!$C$5*(1+D$4)^5*(Inputs!$C$31*(1-Inputs!$C$18)+Inputs!$C$21*Inputs!$C$18-Inputs!$C$22-D$4/(1+D$4)*Inputs!$C$23)*(1+Inputs!$C$24)/($B$6-Inputs!$C$24)/(1+$B$6)^5-Inputs!$C$36,0) | E6: =ROUND(Inputs!$C$5*(1+E$4)^1*(Inputs!$C$30*(1-Inputs!$C$18)+Inputs!$C$21*Inputs!$C$18-Inputs!$C$22-E$4/(1+E$4)*Inputs!$C$23)/(1+$B$6)^1+Inputs!$C$5*(1+E$4)^2*(Inputs!$C$31*(1-Inputs!$C$18)+Inputs!$C$21*Inputs!$C$18-Inputs!$C$22-E$4/(1+E$4)*Inputs!$C$23)/(1+$B$6)^2+Inputs!$C$5*(1+E$4)^3*(Inputs!$C$31*(1-Inputs!$C$18)+Inputs!$C$21*Inputs!$C$18-Inputs!$C$22-E$4/(1+E$4)*Inputs!$C$23)/(1+$B$6)^3+Inputs!$C$5*(1+E$4)^4*(Inputs!$C$31*(1-Inputs!$C$18)+Inputs!$C$21*Inputs!$C$18-Inputs!$C$22-E$4/(1+E$4)*Inputs!$C$23)/(1+$B$6)^4+Inputs!$C$5*(1+E$4)^5*(Inputs!$C$31*(1-Inputs!$C$18)+Inputs!$C$21*Inputs!$C$18-Inputs!$C$22-E$4/(1+E$4)*Inputs!$C$23)/(1+$B$6)^5+Inputs!$C$5*(1+E$4)^5*(Inputs!$C$31*(1-Inputs!$C$18)+Inputs!$C$21*Inputs!$C$18-Inputs!$C$22-E$4/(1+E$4)*Inputs!$C$23)*(1+Inputs!$C$24)/($B$6-Inputs!$C$24)/(1+$B$6)^5-Inputs!$C$36,0) | F6: =ROUND(Inputs!$C$5*(1+F$4)^1*(Inputs!$C$30*(1-Inputs!$C$18)+Inputs!$C$21*Inputs!$C$18-Inputs!$C$22-F$4/(1+F$4)*Inputs!$C$23)/(1+$B$6)^1+Inputs!$C$5*(1+F$4)^2*(Inputs!$C$31*(1-Inputs!$C$18)+Inputs!$C$21*Inputs!$C$18-Inputs!$C$22-F$4/(1+F$4)*Inputs!$C$23)/(1+$B$6)^2+Inputs!$C$5*(1+F$4)^3*(Inputs!$C$31*(1-Inputs!$C$18)+Inputs!$C$21*Inputs!$C$18-Inputs!$C$22-F$4/(1+F$4)*Inputs!$C$23)/(1+$B$6)^3+Inputs!$C$5*(1+F$4)^4*(Inputs!$C$31*(1-Inputs!$C$18)+Inputs!$C$21*Inputs!$C$18-Inputs!$C$22-F$4/(1+F$4)*Inputs!$C$23)/(1+$B$6)^4+Inputs!$C$5*(1+F$4)^5*(Inputs!$C$31*(1-Inputs!$C$18)+Inputs!$C$21*Inputs!$C$18-Inputs!$C$22-F$4/(1+F$4)*Inputs!$C$23)/(1+$B$6)^5+Inputs!$C$5*(1+F$4)^5*(Inputs!$C$31*(1-Inputs!$C$18)+Inputs!$C$21*Inputs!$C$18-Inputs!$C$22-F$4/(1+F$4)*Inputs!$C$23)*(1+Inputs!$C$24)/($B$6-Inputs!$C$24)/(1+$B$6)^5-Inputs!$C$36,0) | G6: =ROUND(Inputs!$C$5*(1+G$4)^1*(Inputs!$C$30*(1-Inputs!$C$18)+Inputs!$C$21*Inputs!$C$18-Inputs!$C$22-G$4/(1+G$4)*Inputs!$C$23)/(1+$B$6)^1+Inputs!$C$5*(1+G$4)^2*(Inputs!$C$31*(1-Inputs!$C$18)+Inputs!$C$21*Inputs!$C$18-Inputs!$C$22-G$4/(1+G$4)*Inputs!$C$23)/(1+$B$6)^2+Inputs!$C$5*(1+G$4)^3*(Inputs!$C$31*(1-Inputs!$C$18)+Inputs!$C$21*Inputs!$C$18-Inputs!$C$22-G$4/(1+G$4)*Inputs!$C$23)/(1+$B$6)^3+Inputs!$C$5*(1+G$4)^4*(Inputs!$C$31*(1-Inputs!$C$18)+Inputs!$C$21*Inputs!$C$18-Inputs!$C$22-G$4/(1+G$4)*Inputs!$C$23)/(1+$B$6)^4+Inputs!$C$5*(1+G$4)^5*(Inputs!$C$31*(1-Inputs!$C$18)+Inputs!$C$21*Inputs!$C$18-Inputs!$C$22-G$4/(1+G$4)*Inputs!$C$23)/(1+$B$6)^5+Inputs!$C$5*(1+G$4)^5*(Inputs!$C$31*(1-Inputs!$C$18)+Inputs!$C$21*Inputs!$C$18-Inputs!$C$22-G$4/(1+G$4)*Inputs!$C$23)*(1+Inputs!$C$24)/($B$6-Inputs!$C$24)/(1+$B$6)^5-Inputs!$C$36,0) | H6: =ROUND(Inputs!$C$5*(1+H$4)^1*(Inputs!$C$30*(1-Inputs!$C$18)+Inputs!$C$21*Inputs!$C$18-Inputs!$C$22-H$4/(1+H$4)*Inputs!$C$23)/(1+$B$6)^1+Inputs!$C$5*(1+H$4)^2*(Inputs!$C$31*(1-Inputs!$C$18)+Inputs!$C$21*Inputs!$C$18-Inputs!$C$22-H$4/(1+H$4)*Inputs!$C$23)/(1+$B$6)^2+Inputs!$C$5*(1+H$4)^3*(Inputs!$C$31*(1-Inputs!$C$18)+Inputs!$C$21*Inputs!$C$18-Inputs!$C$22-H$4/(1+H$4)*Inputs!$C$23)/(1+$B$6)^3+Inputs!$C$5*(1+H$4)^4*(Inputs!$C$31*(1-Inputs!$C$18)+Inputs!$C$21*Inputs!$C$18-Inputs!$C$22-H$4/(1+H$4)*Inputs!$C$23)/(1+$B$6)^4+Inputs!$C$5*(1+H$4)^5*(Inputs!$C$31*(1-Inputs!$C$18)+Inputs!$C$21*Inputs!$C$18-Inputs!$C$22-H$4/(1+H$4)*Inputs!$C$23)/(1+$B$6)^5+Inputs!$C$5*(1+H$4)^5*(Inputs!$C$31*(1-Inputs!$C$18)+Inputs!$C$21*Inputs!$C$18-Inputs!$C$22-H$4/(1+H$4)*Inputs!$C$23)*(1+Inputs!$C$24)/($B$6-Inputs!$C$24)/(1+$B$6)^5-Inputs!$C$36,0) | I6: =ROUND(Inputs!$C$5*(1+I$4)^1*(Inputs!$C$30*(1-Inputs!$C$18)+Inputs!$C$21*Inputs!$C$18-Inputs!$C$22-I$4/(1+I$4)*Inputs!$C$23)/(1+$B$6)^1+Inputs!$C$5*(1+I$4)^2*(Inputs!$C$31*(1-Inputs!$C$18)+Inputs!$C$21*Inputs!$C$18-Inputs!$C$22-I$4/(1+I$4)*Inputs!$C$23)/(1+$B$6)^2+Inputs!$C$5*(1+I$4)^3*(Inputs!$C$31*(1-Inputs!$C$18)+Inputs!$C$21*Inputs!$C$18-Inputs!$C$22-I$4/(1+I$4)*Inputs!$C$23)/(1+$B$6)^3+Inputs!$C$5*(1+I$4)^4*(Inputs!$C$31*(1-Inputs!$C$18)+Inputs!$C$21*Inputs!$C$18-Inputs!$C$22-I$4/(1+I$4)*Inputs!$C$23)/(1+$B$6)^4+Inputs!$C$5*(1+I$4)^5*(Inputs!$C$31*(1-Inputs!$C$18)+Inputs!$C$21*Inputs!$C$18-Inputs!$C$22-I$4/(1+I$4)*Inputs!$C$23)/(1+$B$6)^5+Inputs!$C$5*(1+I$4)^5*(Inputs!$C$31*(1-Inputs!$C$18)+Inputs!$C$21*Inputs!$C$18-Inputs!$C$22-I$4/(1+I$4)*Inputs!$C$23)*(1+Inputs!$C$24)/($B$6-Inputs!$C$24)/(1+$B$6)^5-Inputs!$C$36,0)
B7: 0.0682 | C7: =ROUND(Inputs!$C$5*(1+C$4)^1*(Inputs!$C$30*(1-Inputs!$C$18)+Inputs!$C$21*Inputs!$C$18-Inputs!$C$22-C$4/(1+C$4)*Inputs!$C$23)/(1+$B$7)^1+Inputs!$C$5*(1+C$4)^2*(Inputs!$C$31*(1-Inputs!$C$18)+Inputs!$C$21*Inputs!$C$18-Inputs!$C$22-C$4/(1+C$4)*Inputs!$C$23)/(1+$B$7)^2+Inputs!$C$5*(1+C$4)^3*(Inputs!$C$31*(1-Inputs!$C$18)+Inputs!$C$21*Inputs!$C$18-Inputs!$C$22-C$4/(1+C$4)*Inputs!$C$23)/(1+$B$7)^3+Inputs!$C$5*(1+C$4)^4*(Inputs!$C$31*(1-Inputs!$C$18)+Inputs!$C$21*Inputs!$C$18-Inputs!$C$22-C$4/(1+C$4)*Inputs!$C$23)/(1+$B$7)^4+Inputs!$C$5*(1+C$4)^5*(Inputs!$C$31*(1-Inputs!$C$18)+Inputs!$C$21*Inputs!$C$18-Inputs!$C$22-C$4/(1+C$4)*Inputs!$C$23)/(1+$B$7)^5+Inputs!$C$5*(1+C$4)^5*(Inputs!$C$31*(1-Inputs!$C$18)+Inputs!$C$21*Inputs!$C$18-Inputs!$C$22-C$4/(1+C$4)*Inputs!$C$23)*(1+Inputs!$C$24)/($B$7-Inputs!$C$24)/(1+$B$7)^5-Inputs!$C$36,0) | D7: =ROUND(Inputs!$C$5*(1+D$4)^1*(Inputs!$C$30*(1-Inputs!$C$18)+Inputs!$C$21*Inputs!$C$18-Inputs!$C$22-D$4/(1+D$4)*Inputs!$C$23)/(1+$B$7)^1+Inputs!$C$5*(1+D$4)^2*(Inputs!$C$31*(1-Inputs!$C$18)+Inputs!$C$21*Inputs!$C$18-Inputs!$C$22-D$4/(1+D$4)*Inputs!$C$23)/(1+$B$7)^2+Inputs!$C$5*(1+D$4)^3*(Inputs!$C$31*(1-Inputs!$C$18)+Inputs!$C$21*Inputs!$C$18-Inputs!$C$22-D$4/(1+D$4)*Inputs!$C$23)/(1+$B$7)^3+Inputs!$C$5*(1+D$4)^4*(Inputs!$C$31*(1-Inputs!$C$18)+Inputs!$C$21*Inputs!$C$18-Inputs!$C$22-D$4/(1+D$4)*Inputs!$C$23)/(1+$B$7)^4+Inputs!$C$5*(1+D$4)^5*(Inputs!$C$31*(1-Inputs!$C$18)+Inputs!$C$21*Inputs!$C$18-Inputs!$C$22-D$4/(1+D$4)*Inputs!$C$23)/(1+$B$7)^5+Inputs!$C$5*(1+D$4)^5*(Inputs!$C$31*(1-Inputs!$C$18)+Inputs!$C$21*Inputs!$C$18-Inputs!$C$22-D$4/(1+D$4)*Inputs!$C$23)*(1+Inputs!$C$24)/($B$7-Inputs!$C$24)/(1+$B$7)^5-Inputs!$C$36,0) | E7: =ROUND(Inputs!$C$5*(1+E$4)^1*(Inputs!$C$30*(1-Inputs!$C$18)+Inputs!$C$21*Inputs!$C$18-Inputs!$C$22-E$4/(1+E$4)*Inputs!$C$23)/(1+$B$7)^1+Inputs!$C$5*(1+E$4)^2*(Inputs!$C$31*(1-Inputs!$C$18)+Inputs!$C$21*Inputs!$C$18-Inputs!$C$22-E$4/(1+E$4)*Inputs!$C$23)/(1+$B$7)^2+Inputs!$C$5*(1+E$4)^3*(Inputs!$C$31*(1-Inputs!$C$18)+Inputs!$C$21*Inputs!$C$18-Inputs!$C$22-E$4/(1+E$4)*Inputs!$C$23)/(1+$B$7)^3+Inputs!$C$5*(1+E$4)^4*(Inputs!$C$31*(1-Inputs!$C$18)+Inputs!$C$21*Inputs!$C$18-Inputs!$C$22-E$4/(1+E$4)*Inputs!$C$23)/(1+$B$7)^4+Inputs!$C$5*(1+E$4)^5*(Inputs!$C$31*(1-Inputs!$C$18)+Inputs!$C$21*Inputs!$C$18-Inputs!$C$22-E$4/(1+E$4)*Inputs!$C$23)/(1+$B$7)^5+Inputs!$C$5*(1+E$4)^5*(Inputs!$C$31*(1-Inputs!$C$18)+Inputs!$C$21*Inputs!$C$18-Inputs!$C$22-E$4/(1+E$4)*Inputs!$C$23)*(1+Inputs!$C$24)/($B$7-Inputs!$C$24)/(1+$B$7)^5-Inputs!$C$36,0) | F7: =ROUND(Inputs!$C$5*(1+F$4)^1*(Inputs!$C$30*(1-Inputs!$C$18)+Inputs!$C$21*Inputs!$C$18-Inputs!$C$22-F$4/(1+F$4)*Inputs!$C$23)/(1+$B$7)^1+Inputs!$C$5*(1+F$4)^2*(Inputs!$C$31*(1-Inputs!$C$18)+Inputs!$C$21*Inputs!$C$18-Inputs!$C$22-F$4/(1+F$4)*Inputs!$C$23)/(1+$B$7)^2+Inputs!$C$5*(1+F$4)^3*(Inputs!$C$31*(1-Inputs!$C$18)+Inputs!$C$21*Inputs!$C$18-Inputs!$C$22-F$4/(1+F$4)*Inputs!$C$23)/(1+$B$7)^3+Inputs!$C$5*(1+F$4)^4*(Inputs!$C$31*(1-Inputs!$C$18)+Inputs!$C$21*Inputs!$C$18-Inputs!$C$22-F$4/(1+F$4)*Inputs!$C$23)/(1+$B$7)^4+Inputs!$C$5*(1+F$4)^5*(Inputs!$C$31*(1-Inputs!$C$18)+Inputs!$C$21*Inputs!$C$18-Inputs!$C$22-F$4/(1+F$4)*Inputs!$C$23)/(1+$B$7)^5+Inputs!$C$5*(1+F$4)^5*(Inputs!$C$31*(1-Inputs!$C$18)+Inputs!$C$21*Inputs!$C$18-Inputs!$C$22-F$4/(1+F$4)*Inputs!$C$23)*(1+Inputs!$C$24)/($B$7-Inputs!$C$24)/(1+$B$7)^5-Inputs!$C$36,0) | G7: =ROUND(Inputs!$C$5*(1+G$4)^1*(Inputs!$C$30*(1-Inputs!$C$18)+Inputs!$C$21*Inputs!$C$18-Inputs!$C$22-G$4/(1+G$4)*Inputs!$C$23)/(1+$B$7)^1+Inputs!$C$5*(1+G$4)^2*(Inputs!$C$31*(1-Inputs!$C$18)+Inputs!$C$21*Inputs!$C$18-Inputs!$C$22-G$4/(1+G$4)*Inputs!$C$23)/(1+$B$7)^2+Inputs!$C$5*(1+G$4)^3*(Inputs!$C$31*(1-Inputs!$C$18)+Inputs!$C$21*Inputs!$C$18-Inputs!$C$22-G$4/(1+G$4)*Inputs!$C$23)/(1+$B$7)^3+Inputs!$C$5*(1+G$4)^4*(Inputs!$C$31*(1-Inputs!$C$18)+Inputs!$C$21*Inputs!$C$18-Inputs!$C$22-G$4/(1+G$4)*Inputs!$C$23)/(1+$B$7)^4+Inputs!$C$5*(1+G$4)^5*(Inputs!$C$31*(1-Inputs!$C$18)+Inputs!$C$21*Inputs!$C$18-Inputs!$C$22-G$4/(1+G$4)*Inputs!$C$23)/(1+$B$7)^5+Inputs!$C$5*(1+G$4)^5*(Inputs!$C$31*(1-Inputs!$C$18)+Inputs!$C$21*Inputs!$C$18-Inputs!$C$22-G$4/(1+G$4)*Inputs!$C$23)*(1+Inputs!$C$24)/($B$7-Inputs!$C$24)/(1+$B$7)^5-Inputs!$C$36,0) | H7: =ROUND(Inputs!$C$5*(1+H$4)^1*(Inputs!$C$30*(1-Inputs!$C$18)+Inputs!$C$21*Inputs!$C$18-Inputs!$C$22-H$4/(1+H$4)*Inputs!$C$23)/(1+$B$7)^1+Inputs!$C$5*(1+H$4)^2*(Inputs!$C$31*(1-Inputs!$C$18)+Inputs!$C$21*Inputs!$C$18-Inputs!$C$22-H$4/(1+H$4)*Inputs!$C$23)/(1+$B$7)^2+Inputs!$C$5*(1+H$4)^3*(Inputs!$C$31*(1-Inputs!$C$18)+Inputs!$C$21*Inputs!$C$18-Inputs!$C$22-H$4/(1+H$4)*Inputs!$C$23)/(1+$B$7)^3+Inputs!$C$5*(1+H$4)^4*(Inputs!$C$31*(1-Inputs!$C$18)+Inputs!$C$21*Inputs!$C$18-Inputs!$C$22-H$4/(1+H$4)*Inputs!$C$23)/(1+$B$7)^4+Inputs!$C$5*(1+H$4)^5*(Inputs!$C$31*(1-Inputs!$C$18)+Inputs!$C$21*Inputs!$C$18-Inputs!$C$22-H$4/(1+H$4)*Inputs!$C$23)/(1+$B$7)^5+Inputs!$C$5*(1+H$4)^5*(Inputs!$C$31*(1-Inputs!$C$18)+Inputs!$C$21*Inputs!$C$18-Inputs!$C$22-H$4/(1+H$4)*Inputs!$C$23)*(1+Inputs!$C$24)/($B$7-Inputs!$C$24)/(1+$B$7)^5-Inputs!$C$36,0) | I7: =ROUND(Inputs!$C$5*(1+I$4)^1*(Inputs!$C$30*(1-Inputs!$C$18)+Inputs!$C$21*Inputs!$C$18-Inputs!$C$22-I$4/(1+I$4)*Inputs!$C$23)/(1+$B$7)^1+Inputs!$C$5*(1+I$4)^2*(Inputs!$C$31*(1-Inputs!$C$18)+Inputs!$C$21*Inputs!$C$18-Inputs!$C$22-I$4/(1+I$4)*Inputs!$C$23)/(1+$B$7)^2+Inputs!$C$5*(1+I$4)^3*(Inputs!$C$31*(1-Inputs!$C$18)+Inputs!$C$21*Inputs!$C$18-Inputs!$C$22-I$4/(1+I$4)*Inputs!$C$23)/(1+$B$7)^3+Inputs!$C$5*(1+I$4)^4*(Inputs!$C$31*(1-Inputs!$C$18)+Inputs!$C$21*Inputs!$C$18-Inputs!$C$22-I$4/(1+I$4)*Inputs!$C$23)/(1+$B$7)^4+Inputs!$C$5*(1+I$4)^5*(Inputs!$C$31*(1-Inputs!$C$18)+Inputs!$C$21*Inputs!$C$18-Inputs!$C$22-I$4/(1+I$4)*Inputs!$C$23)/(1+$B$7)^5+Inputs!$C$5*(1+I$4)^5*(Inputs!$C$31*(1-Inputs!$C$18)+Inputs!$C$21*Inputs!$C$18-Inputs!$C$22-I$4/(1+I$4)*Inputs!$C$23)*(1+Inputs!$C$24)/($B$7-Inputs!$C$24)/(1+$B$7)^5-Inputs!$C$36,0)
B8: 0.08 | C8: =ROUND(Inputs!$C$5*(1+C$4)^1*(Inputs!$C$30*(1-Inputs!$C$18)+Inputs!$C$21*Inputs!$C$18-Inputs!$C$22-C$4/(1+C$4)*Inputs!$C$23)/(1+$B$8)^1+Inputs!$C$5*(1+C$4)^2*(Inputs!$C$31*(1-Inputs!$C$18)+Inputs!$C$21*Inputs!$C$18-Inputs!$C$22-C$4/(1+C$4)*Inputs!$C$23)/(1+$B$8)^2+Inputs!$C$5*(1+C$4)^3*(Inputs!$C$31*(1-Inputs!$C$18)+Inputs!$C$21*Inputs!$C$18-Inputs!$C$22-C$4/(1+C$4)*Inputs!$C$23)/(1+$B$8)^3+Inputs!$C$5*(1+C$4)^4*(Inputs!$C$31*(1-Inputs!$C$18)+Inputs!$C$21*Inputs!$C$18-Inputs!$C$22-C$4/(1+C$4)*Inputs!$C$23)/(1+$B$8)^4+Inputs!$C$5*(1+C$4)^5*(Inputs!$C$31*(1-Inputs!$C$18)+Inputs!$C$21*Inputs!$C$18-Inputs!$C$22-C$4/(1+C$4)*Inputs!$C$23)/(1+$B$8)^5+Inputs!$C$5*(1+C$4)^5*(Inputs!$C$31*(1-Inputs!$C$18)+Inputs!$C$21*Inputs!$C$18-Inputs!$C$22-C$4/(1+C$4)*Inputs!$C$23)*(1+Inputs!$C$24)/($B$8-Inputs!$C$24)/(1+$B$8)^5-Inputs!$C$36,0) | D8: =ROUND(Inputs!$C$5*(1+D$4)^1*(Inputs!$C$30*(1-Inputs!$C$18)+Inputs!$C$21*Inputs!$C$18-Inputs!$C$22-D$4/(1+D$4)*Inputs!$C$23)/(1+$B$8)^1+Inputs!$C$5*(1+D$4)^2*(Inputs!$C$31*(1-Inputs!$C$18)+Inputs!$C$21*Inputs!$C$18-Inputs!$C$22-D$4/(1+D$4)*Inputs!$C$23)/(1+$B$8)^2+Inputs!$C$5*(1+D$4)^3*(Inputs!$C$31*(1-Inputs!$C$18)+Inputs!$C$21*Inputs!$C$18-Inputs!$C$22-D$4/(1+D$4)*Inputs!$C$23)/(1+$B$8)^3+Inputs!$C$5*(1+D$4)^4*(Inputs!$C$31*(1-Inputs!$C$18)+Inputs!$C$21*Inputs!$C$18-Inputs!$C$22-D$4/(1+D$4)*Inputs!$C$23)/(1+$B$8)^4+Inputs!$C$5*(1+D$4)^5*(Inputs!$C$31*(1-Inputs!$C$18)+Inputs!$C$21*Inputs!$C$18-Inputs!$C$22-D$4/(1+D$4)*Inputs!$C$23)/(1+$B$8)^5+Inputs!$C$5*(1+D$4)^5*(Inputs!$C$31*(1-Inputs!$C$18)+Inputs!$C$21*Inputs!$C$18-Inputs!$C$22-D$4/(1+D$4)*Inputs!$C$23)*(1+Inputs!$C$24)/($B$8-Inputs!$C$24)/(1+$B$8)^5-Inputs!$C$36,0) | E8: =ROUND(Inputs!$C$5*(1+E$4)^1*(Inputs!$C$30*(1-Inputs!$C$18)+Inputs!$C$21*Inputs!$C$18-Inputs!$C$22-E$4/(1+E$4)*Inputs!$C$23)/(1+$B$8)^1+Inputs!$C$5*(1+E$4)^2*(Inputs!$C$31*(1-Inputs!$C$18)+Inputs!$C$21*Inputs!$C$18-Inputs!$C$22-E$4/(1+E$4)*Inputs!$C$23)/(1+$B$8)^2+Inputs!$C$5*(1+E$4)^3*(Inputs!$C$31*(1-Inputs!$C$18)+Inputs!$C$21*Inputs!$C$18-Inputs!$C$22-E$4/(1+E$4)*Inputs!$C$23)/(1+$B$8)^3+Inputs!$C$5*(1+E$4)^4*(Inputs!$C$31*(1-Inputs!$C$18)+Inputs!$C$21*Inputs!$C$18-Inputs!$C$22-E$4/(1+E$4)*Inputs!$C$23)/(1+$B$8)^4+Inputs!$C$5*(1+E$4)^5*(Inputs!$C$31*(1-Inputs!$C$18)+Inputs!$C$21*Inputs!$C$18-Inputs!$C$22-E$4/(1+E$4)*Inputs!$C$23)/(1+$B$8)^5+Inputs!$C$5*(1+E$4)^5*(Inputs!$C$31*(1-Inputs!$C$18)+Inputs!$C$21*Inputs!$C$18-Inputs!$C$22-E$4/(1+E$4)*Inputs!$C$23)*(1+Inputs!$C$24)/($B$8-Inputs!$C$24)/(1+$B$8)^5-Inputs!$C$36,0) | F8: =ROUND(Inputs!$C$5*(1+F$4)^1*(Inputs!$C$30*(1-Inputs!$C$18)+Inputs!$C$21*Inputs!$C$18-Inputs!$C$22-F$4/(1+F$4)*Inputs!$C$23)/(1+$B$8)^1+Inputs!$C$5*(1+F$4)^2*(Inputs!$C$31*(1-Inputs!$C$18)+Inputs!$C$21*Inputs!$C$18-Inputs!$C$22-F$4/(1+F$4)*Inputs!$C$23)/(1+$B$8)^2+Inputs!$C$5*(1+F$4)^3*(Inputs!$C$31*(1-Inputs!$C$18)+Inputs!$C$21*Inputs!$C$18-Inputs!$C$22-F$4/(1+F$4)*Inputs!$C$23)/(1+$B$8)^3+Inputs!$C$5*(1+F$4)^4*(Inputs!$C$31*(1-Inputs!$C$18)+Inputs!$C$21*Inputs!$C$18-Inputs!$C$22-F$4/(1+F$4)*Inputs!$C$23)/(1+$B$8)^4+Inputs!$C$5*(1+F$4)^5*(Inputs!$C$31*(1-Inputs!$C$18)+Inputs!$C$21*Inputs!$C$18-Inputs!$C$22-F$4/(1+F$4)*Inputs!$C$23)/(1+$B$8)^5+Inputs!$C$5*(1+F$4)^5*(Inputs!$C$31*(1-Inputs!$C$18)+Inputs!$C$21*Inputs!$C$18-Inputs!$C$22-F$4/(1+F$4)*Inputs!$C$23)*(1+Inputs!$C$24)/($B$8-Inputs!$C$24)/(1+$B$8)^5-Inputs!$C$36,0) | G8: =ROUND(Inputs!$C$5*(1+G$4)^1*(Inputs!$C$30*(1-Inputs!$C$18)+Inputs!$C$21*Inputs!$C$18-Inputs!$C$22-G$4/(1+G$4)*Inputs!$C$23)/(1+$B$8)^1+Inputs!$C$5*(1+G$4)^2*(Inputs!$C$31*(1-Inputs!$C$18)+Inputs!$C$21*Inputs!$C$18-Inputs!$C$22-G$4/(1+G$4)*Inputs!$C$23)/(1+$B$8)^2+Inputs!$C$5*(1+G$4)^3*(Inputs!$C$31*(1-Inputs!$C$18)+Inputs!$C$21*Inputs!$C$18-Inputs!$C$22-G$4/(1+G$4)*Inputs!$C$23)/(1+$B$8)^3+Inputs!$C$5*(1+G$4)^4*(Inputs!$C$31*(1-Inputs!$C$18)+Inputs!$C$21*Inputs!$C$18-Inputs!$C$22-G$4/(1+G$4)*Inputs!$C$23)/(1+$B$8)^4+Inputs!$C$5*(1+G$4)^5*(Inputs!$C$31*(1-Inputs!$C$18)+Inputs!$C$21*Inputs!$C$18-Inputs!$C$22-G$4/(1+G$4)*Inputs!$C$23)/(1+$B$8)^5+Inputs!$C$5*(1+G$4)^5*(Inputs!$C$31*(1-Inputs!$C$18)+Inputs!$C$21*Inputs!$C$18-Inputs!$C$22-G$4/(1+G$4)*Inputs!$C$23)*(1+Inputs!$C$24)/($B$8-Inputs!$C$24)/(1+$B$8)^5-Inputs!$C$36,0) | H8: =ROUND(Inputs!$C$5*(1+H$4)^1*(Inputs!$C$30*(1-Inputs!$C$18)+Inputs!$C$21*Inputs!$C$18-Inputs!$C$22-H$4/(1+H$4)*Inputs!$C$23)/(1+$B$8)^1+Inputs!$C$5*(1+H$4)^2*(Inputs!$C$31*(1-Inputs!$C$18)+Inputs!$C$21*Inputs!$C$18-Inputs!$C$22-H$4/(1+H$4)*Inputs!$C$23)/(1+$B$8)^2+Inputs!$C$5*(1+H$4)^3*(Inputs!$C$31*(1-Inputs!$C$18)+Inputs!$C$21*Inputs!$C$18-Inputs!$C$22-H$4/(1+H$4)*Inputs!$C$23)/(1+$B$8)^3+Inputs!$C$5*(1+H$4)^4*(Inputs!$C$31*(1-Inputs!$C$18)+Inputs!$C$21*Inputs!$C$18-Inputs!$C$22-H$4/(1+H$4)*Inputs!$C$23)/(1+$B$8)^4+Inputs!$C$5*(1+H$4)^5*(Inputs!$C$31*(1-Inputs!$C$18)+Inputs!$C$21*Inputs!$C$18-Inputs!$C$22-H$4/(1+H$4)*Inputs!$C$23)/(1+$B$8)^5+Inputs!$C$5*(1+H$4)^5*(Inputs!$C$31*(1-Inputs!$C$18)+Inputs!$C$21*Inputs!$C$18-Inputs!$C$22-H$4/(1+H$4)*Inputs!$C$23)*(1+Inputs!$C$24)/($B$8-Inputs!$C$24)/(1+$B$8)^5-Inputs!$C$36,0) | I8: =ROUND(Inputs!$C$5*(1+I$4)^1*(Inputs!$C$30*(1-Inputs!$C$18)+Inputs!$C$21*Inputs!$C$18-Inputs!$C$22-I$4/(1+I$4)*Inputs!$C$23)/(1+$B$8)^1+Inputs!$C$5*(1+I$4)^2*(Inputs!$C$31*(1-Inputs!$C$18)+Inputs!$C$21*Inputs!$C$18-Inputs!$C$22-I$4/(1+I$4)*Inputs!$C$23)/(1+$B$8)^2+Inputs!$C$5*(1+I$4)^3*(Inputs!$C$31*(1-Inputs!$C$18)+Inputs!$C$21*Inputs!$C$18-Inputs!$C$22-I$4/(1+I$4)*Inputs!$C$23)/(1+$B$8)^3+Inputs!$C$5*(1+I$4)^4*(Inputs!$C$31*(1-Inputs!$C$18)+Inputs!$C$21*Inputs!$C$18-Inputs!$C$22-I$4/(1+I$4)*Inputs!$C$23)/(1+$B$8)^4+Inputs!$C$5*(1+I$4)^5*(Inputs!$C$31*(1-Inputs!$C$18)+Inputs!$C$21*Inputs!$C$18-Inputs!$C$22-I$4/(1+I$4)*Inputs!$C$23)/(1+$B$8)^5+Inputs!$C$5*(1+I$4)^5*(Inputs!$C$31*(1-Inputs!$C$18)+Inputs!$C$21*Inputs!$C$18-Inputs!$C$22-I$4/(1+I$4)*Inputs!$C$23)*(1+Inputs!$C$24)/($B$8-Inputs!$C$24)/(1+$B$8)^5-Inputs!$C$36,0)
B9: 0.09 | C9: =ROUND(Inputs!$C$5*(1+C$4)^1*(Inputs!$C$30*(1-Inputs!$C$18)+Inputs!$C$21*Inputs!$C$18-Inputs!$C$22-C$4/(1+C$4)*Inputs!$C$23)/(1+$B$9)^1+Inputs!$C$5*(1+C$4)^2*(Inputs!$C$31*(1-Inputs!$C$18)+Inputs!$C$21*Inputs!$C$18-Inputs!$C$22-C$4/(1+C$4)*Inputs!$C$23)/(1+$B$9)^2+Inputs!$C$5*(1+C$4)^3*(Inputs!$C$31*(1-Inputs!$C$18)+Inputs!$C$21*Inputs!$C$18-Inputs!$C$22-C$4/(1+C$4)*Inputs!$C$23)/(1+$B$9)^3+Inputs!$C$5*(1+C$4)^4*(Inputs!$C$31*(1-Inputs!$C$18)+Inputs!$C$21*Inputs!$C$18-Inputs!$C$22-C$4/(1+C$4)*Inputs!$C$23)/(1+$B$9)^4+Inputs!$C$5*(1+C$4)^5*(Inputs!$C$31*(1-Inputs!$C$18)+Inputs!$C$21*Inputs!$C$18-Inputs!$C$22-C$4/(1+C$4)*Inputs!$C$23)/(1+$B$9)^5+Inputs!$C$5*(1+C$4)^5*(Inputs!$C$31*(1-Inputs!$C$18)+Inputs!$C$21*Inputs!$C$18-Inputs!$C$22-C$4/(1+C$4)*Inputs!$C$23)*(1+Inputs!$C$24)/($B$9-Inputs!$C$24)/(1+$B$9)^5-Inputs!$C$36,0) | D9: =ROUND(Inputs!$C$5*(1+D$4)^1*(Inputs!$C$30*(1-Inputs!$C$18)+Inputs!$C$21*Inputs!$C$18-Inputs!$C$22-D$4/(1+D$4)*Inputs!$C$23)/(1+$B$9)^1+Inputs!$C$5*(1+D$4)^2*(Inputs!$C$31*(1-Inputs!$C$18)+Inputs!$C$21*Inputs!$C$18-Inputs!$C$22-D$4/(1+D$4)*Inputs!$C$23)/(1+$B$9)^2+Inputs!$C$5*(1+D$4)^3*(Inputs!$C$31*(1-Inputs!$C$18)+Inputs!$C$21*Inputs!$C$18-Inputs!$C$22-D$4/(1+D$4)*Inputs!$C$23)/(1+$B$9)^3+Inputs!$C$5*(1+D$4)^4*(Inputs!$C$31*(1-Inputs!$C$18)+Inputs!$C$21*Inputs!$C$18-Inputs!$C$22-D$4/(1+D$4)*Inputs!$C$23)/(1+$B$9)^4+Inputs!$C$5*(1+D$4)^5*(Inputs!$C$31*(1-Inputs!$C$18)+Inputs!$C$21*Inputs!$C$18-Inputs!$C$22-D$4/(1+D$4)*Inputs!$C$23)/(1+$B$9)^5+Inputs!$C$5*(1+D$4)^5*(Inputs!$C$31*(1-Inputs!$C$18)+Inputs!$C$21*Inputs!$C$18-Inputs!$C$22-D$4/(1+D$4)*Inputs!$C$23)*(1+Inputs!$C$24)/($B$9-Inputs!$C$24)/(1+$B$9)^5-Inputs!$C$36,0) | E9: =ROUND(Inputs!$C$5*(1+E$4)^1*(Inputs!$C$30*(1-Inputs!$C$18)+Inputs!$C$21*Inputs!$C$18-Inputs!$C$22-E$4/(1+E$4)*Inputs!$C$23)/(1+$B$9)^1+Inputs!$C$5*(1+E$4)^2*(Inputs!$C$31*(1-Inputs!$C$18)+Inputs!$C$21*Inputs!$C$18-Inputs!$C$22-E$4/(1+E$4)*Inputs!$C$23)/(1+$B$9)^2+Inputs!$C$5*(1+E$4)^3*(Inputs!$C$31*(1-Inputs!$C$18)+Inputs!$C$21*Inputs!$C$18-Inputs!$C$22-E$4/(1+E$4)*Inputs!$C$23)/(1+$B$9)^3+Inputs!$C$5*(1+E$4)^4*(Inputs!$C$31*(1-Inputs!$C$18)+Inputs!$C$21*Inputs!$C$18-Inputs!$C$22-E$4/(1+E$4)*Inputs!$C$23)/(1+$B$9)^4+Inputs!$C$5*(1+E$4)^5*(Inputs!$C$31*(1-Inputs!$C$18)+Inputs!$C$21*Inputs!$C$18-Inputs!$C$22-E$4/(1+E$4)*Inputs!$C$23)/(1+$B$9)^5+Inputs!$C$5*(1+E$4)^5*(Inputs!$C$31*(1-Inputs!$C$18)+Inputs!$C$21*Inputs!$C$18-Inputs!$C$22-E$4/(1+E$4)*Inputs!$C$23)*(1+Inputs!$C$24)/($B$9-Inputs!$C$24)/(1+$B$9)^5-Inputs!$C$36,0) | F9: =ROUND(Inputs!$C$5*(1+F$4)^1*(Inputs!$C$30*(1-Inputs!$C$18)+Inputs!$C$21*Inputs!$C$18-Inputs!$C$22-F$4/(1+F$4)*Inputs!$C$23)/(1+$B$9)^1+Inputs!$C$5*(1+F$4)^2*(Inputs!$C$31*(1-Inputs!$C$18)+Inputs!$C$21*Inputs!$C$18-Inputs!$C$22-F$4/(1+F$4)*Inputs!$C$23)/(1+$B$9)^2+Inputs!$C$5*(1+F$4)^3*(Inputs!$C$31*(1-Inputs!$C$18)+Inputs!$C$21*Inputs!$C$18-Inputs!$C$22-F$4/(1+F$4)*Inputs!$C$23)/(1+$B$9)^3+Inputs!$C$5*(1+F$4)^4*(Inputs!$C$31*(1-Inputs!$C$18)+Inputs!$C$21*Inputs!$C$18-Inputs!$C$22-F$4/(1+F$4)*Inputs!$C$23)/(1+$B$9)^4+Inputs!$C$5*(1+F$4)^5*(Inputs!$C$31*(1-Inputs!$C$18)+Inputs!$C$21*Inputs!$C$18-Inputs!$C$22-F$4/(1+F$4)*Inputs!$C$23)/(1+$B$9)^5+Inputs!$C$5*(1+F$4)^5*(Inputs!$C$31*(1-Inputs!$C$18)+Inputs!$C$21*Inputs!$C$18-Inputs!$C$22-F$4/(1+F$4)*Inputs!$C$23)*(1+Inputs!$C$24)/($B$9-Inputs!$C$24)/(1+$B$9)^5-Inputs!$C$36,0) | G9: =ROUND(Inputs!$C$5*(1+G$4)^1*(Inputs!$C$30*(1-Inputs!$C$18)+Inputs!$C$21*Inputs!$C$18-Inputs!$C$22-G$4/(1+G$4)*Inputs!$C$23)/(1+$B$9)^1+Inputs!$C$5*(1+G$4)^2*(Inputs!$C$31*(1-Inputs!$C$18)+Inputs!$C$21*Inputs!$C$18-Inputs!$C$22-G$4/(1+G$4)*Inputs!$C$23)/(1+$B$9)^2+Inputs!$C$5*(1+G$4)^3*(Inputs!$C$31*(1-Inputs!$C$18)+Inputs!$C$21*Inputs!$C$18-Inputs!$C$22-G$4/(1+G$4)*Inputs!$C$23)/(1+$B$9)^3+Inputs!$C$5*(1+G$4)^4*(Inputs!$C$31*(1-Inputs!$C$18)+Inputs!$C$21*Inputs!$C$18-Inputs!$C$22-G$4/(1+G$4)*Inputs!$C$23)/(1+$B$9)^4+Inputs!$C$5*(1+G$4)^5*(Inputs!$C$31*(1-Inputs!$C$18)+Inputs!$C$21*Inputs!$C$18-Inputs!$C$22-G$4/(1+G$4)*Inputs!$C$23)/(1+$B$9)^5+Inputs!$C$5*(1+G$4)^5*(Inputs!$C$31*(1-Inputs!$C$18)+Inputs!$C$21*Inputs!$C$18-Inputs!$C$22-G$4/(1+G$4)*Inputs!$C$23)*(1+Inputs!$C$24)/($B$9-Inputs!$C$24)/(1+$B$9)^5-Inputs!$C$36,0) | H9: =ROUND(Inputs!$C$5*(1+H$4)^1*(Inputs!$C$30*(1-Inputs!$C$18)+Inputs!$C$21*Inputs!$C$18-Inputs!$C$22-H$4/(1+H$4)*Inputs!$C$23)/(1+$B$9)^1+Inputs!$C$5*(1+H$4)^2*(Inputs!$C$31*(1-Inputs!$C$18)+Inputs!$C$21*Inputs!$C$18-Inputs!$C$22-H$4/(1+H$4)*Inputs!$C$23)/(1+$B$9)^2+Inputs!$C$5*(1+H$4)^3*(Inputs!$C$31*(1-Inputs!$C$18)+Inputs!$C$21*Inputs!$C$18-Inputs!$C$22-H$4/(1+H$4)*Inputs!$C$23)/(1+$B$9)^3+Inputs!$C$5*(1+H$4)^4*(Inputs!$C$31*(1-Inputs!$C$18)+Inputs!$C$21*Inputs!$C$18-Inputs!$C$22-H$4/(1+H$4)*Inputs!$C$23)/(1+$B$9)^4+Inputs!$C$5*(1+H$4)^5*(Inputs!$C$31*(1-Inputs!$C$18)+Inputs!$C$21*Inputs!$C$18-Inputs!$C$22-H$4/(1+H$4)*Inputs!$C$23)/(1+$B$9)^5+Inputs!$C$5*(1+H$4)^5*(Inputs!$C$31*(1-Inputs!$C$18)+Inputs!$C$21*Inputs!$C$18-Inputs!$C$22-H$4/(1+H$4)*Inputs!$C$23)*(1+Inputs!$C$24)/($B$9-Inputs!$C$24)/(1+$B$9)^5-Inputs!$C$36,0) | I9: =ROUND(Inputs!$C$5*(1+I$4)^1*(Inputs!$C$30*(1-Inputs!$C$18)+Inputs!$C$21*Inputs!$C$18-Inputs!$C$22-I$4/(1+I$4)*Inputs!$C$23)/(1+$B$9)^1+Inputs!$C$5*(1+I$4)^2*(Inputs!$C$31*(1-Inputs!$C$18)+Inputs!$C$21*Inputs!$C$18-Inputs!$C$22-I$4/(1+I$4)*Inputs!$C$23)/(1+$B$9)^2+Inputs!$C$5*(1+I$4)^3*(Inputs!$C$31*(1-Inputs!$C$18)+Inputs!$C$21*Inputs!$C$18-Inputs!$C$22-I$4/(1+I$4)*Inputs!$C$23)/(1+$B$9)^3+Inputs!$C$5*(1+I$4)^4*(Inputs!$C$31*(1-Inputs!$C$18)+Inputs!$C$21*Inputs!$C$18-Inputs!$C$22-I$4/(1+I$4)*Inputs!$C$23)/(1+$B$9)^4+Inputs!$C$5*(1+I$4)^5*(Inputs!$C$31*(1-Inputs!$C$18)+Inputs!$C$21*Inputs!$C$18-Inputs!$C$22-I$4/(1+I$4)*Inputs!$C$23)/(1+$B$9)^5+Inputs!$C$5*(1+I$4)^5*(Inputs!$C$31*(1-Inputs!$C$18)+Inputs!$C$21*Inputs!$C$18-Inputs!$C$22-I$4/(1+I$4)*Inputs!$C$23)*(1+Inputs!$C$24)/($B$9-Inputs!$C$24)/(1+$B$9)^5-Inputs!$C$36,0)
B10: 0.1 | C10: =ROUND(Inputs!$C$5*(1+C$4)^1*(Inputs!$C$30*(1-Inputs!$C$18)+Inputs!$C$21*Inputs!$C$18-Inputs!$C$22-C$4/(1+C$4)*Inputs!$C$23)/(1+$B$10)^1+Inputs!$C$5*(1+C$4)^2*(Inputs!$C$31*(1-Inputs!$C$18)+Inputs!$C$21*Inputs!$C$18-Inputs!$C$22-C$4/(1+C$4)*Inputs!$C$23)/(1+$B$10)^2+Inputs!$C$5*(1+C$4)^3*(Inputs!$C$31*(1-Inputs!$C$18)+Inputs!$C$21*Inputs!$C$18-Inputs!$C$22-C$4/(1+C$4)*Inputs!$C$23)/(1+$B$10)^3+Inputs!$C$5*(1+C$4)^4*(Inputs!$C$31*(1-Inputs!$C$18)+Inputs!$C$21*Inputs!$C$18-Inputs!$C$22-C$4/(1+C$4)*Inputs!$C$23)/(1+$B$10)^4+Inputs!$C$5*(1+C$4)^5*(Inputs!$C$31*(1-Inputs!$C$18)+Inputs!$C$21*Inputs!$C$18-Inputs!$C$22-C$4/(1+C$4)*Inputs!$C$23)/(1+$B$10)^5+Inputs!$C$5*(1+C$4)^5*(Inputs!$C$31*(1-Inputs!$C$18)+Inputs!$C$21*Inputs!$C$18-Inputs!$C$22-C$4/(1+C$4)*Inputs!$C$23)*(1+Inputs!$C$24)/($B$10-Inputs!$C$24)/(1+$B$10)^5-Inputs!$C$36,0) | D10: =ROUND(Inputs!$C$5*(1+D$4)^1*(Inputs!$C$30*(1-Inputs!$C$18)+Inputs!$C$21*Inputs!$C$18-Inputs!$C$22-D$4/(1+D$4)*Inputs!$C$23)/(1+$B$10)^1+Inputs!$C$5*(1+D$4)^2*(Inputs!$C$31*(1-Inputs!$C$18)+Inputs!$C$21*Inputs!$C$18-Inputs!$C$22-D$4/(1+D$4)*Inputs!$C$23)/(1+$B$10)^2+Inputs!$C$5*(1+D$4)^3*(Inputs!$C$31*(1-Inputs!$C$18)+Inputs!$C$21*Inputs!$C$18-Inputs!$C$22-D$4/(1+D$4)*Inputs!$C$23)/(1+$B$10)^3+Inputs!$C$5*(1+D$4)^4*(Inputs!$C$31*(1-Inputs!$C$18)+Inputs!$C$21*Inputs!$C$18-Inputs!$C$22-D$4/(1+D$4)*Inputs!$C$23)/(1+$B$10)^4+Inputs!$C$5*(1+D$4)^5*(Inputs!$C$31*(1-Inputs!$C$18)+Inputs!$C$21*Inputs!$C$18-Inputs!$C$22-D$4/(1+D$4)*Inputs!$C$23)/(1+$B$10)^5+Inputs!$C$5*(1+D$4)^5*(Inputs!$C$31*(1-Inputs!$C$18)+Inputs!$C$21*Inputs!$C$18-Inputs!$C$22-D$4/(1+D$4)*Inputs!$C$23)*(1+Inputs!$C$24)/($B$10-Inputs!$C$24)/(1+$B$10)^5-Inputs!$C$36,0) | E10: =ROUND(Inputs!$C$5*(1+E$4)^1*(Inputs!$C$30*(1-Inputs!$C$18)+Inputs!$C$21*Inputs!$C$18-Inputs!$C$22-E$4/(1+E$4)*Inputs!$C$23)/(1+$B$10)^1+Inputs!$C$5*(1+E$4)^2*(Inputs!$C$31*(1-Inputs!$C$18)+Inputs!$C$21*Inputs!$C$18-Inputs!$C$22-E$4/(1+E$4)*Inputs!$C$23)/(1+$B$10)^2+Inputs!$C$5*(1+E$4)^3*(Inputs!$C$31*(1-Inputs!$C$18)+Inputs!$C$21*Inputs!$C$18-Inputs!$C$22-E$4/(1+E$4)*Inputs!$C$23)/(1+$B$10)^3+Inputs!$C$5*(1+E$4)^4*(Inputs!$C$31*(1-Inputs!$C$18)+Inputs!$C$21*Inputs!$C$18-Inputs!$C$22-E$4/(1+E$4)*Inputs!$C$23)/(1+$B$10)^4+Inputs!$C$5*(1+E$4)^5*(Inputs!$C$31*(1-Inputs!$C$18)+Inputs!$C$21*Inputs!$C$18-Inputs!$C$22-E$4/(1+E$4)*Inputs!$C$23)/(1+$B$10)^5+Inputs!$C$5*(1+E$4)^5*(Inputs!$C$31*(1-Inputs!$C$18)+Inputs!$C$21*Inputs!$C$18-Inputs!$C$22-E$4/(1+E$4)*Inputs!$C$23)*(1+Inputs!$C$24)/($B$10-Inputs!$C$24)/(1+$B$10)^5-Inputs!$C$36,0) | F10: =ROUND(Inputs!$C$5*(1+F$4)^1*(Inputs!$C$30*(1-Inputs!$C$18)+Inputs!$C$21*Inputs!$C$18-Inputs!$C$22-F$4/(1+F$4)*Inputs!$C$23)/(1+$B$10)^1+Inputs!$C$5*(1+F$4)^2*(Inputs!$C$31*(1-Inputs!$C$18)+Inputs!$C$21*Inputs!$C$18-Inputs!$C$22-F$4/(1+F$4)*Inputs!$C$23)/(1+$B$10)^2+Inputs!$C$5*(1+F$4)^3*(Inputs!$C$31*(1-Inputs!$C$18)+Inputs!$C$21*Inputs!$C$18-Inputs!$C$22-F$4/(1+F$4)*Inputs!$C$23)/(1+$B$10)^3+Inputs!$C$5*(1+F$4)^4*(Inputs!$C$31*(1-Inputs!$C$18)+Inputs!$C$21*Inputs!$C$18-Inputs!$C$22-F$4/(1+F$4)*Inputs!$C$23)/(1+$B$10)^4+Inputs!$C$5*(1+F$4)^5*(Inputs!$C$31*(1-Inputs!$C$18)+Inputs!$C$21*Inputs!$C$18-Inputs!$C$22-F$4/(1+F$4)*Inputs!$C$23)/(1+$B$10)^5+Inputs!$C$5*(1+F$4)^5*(Inputs!$C$31*(1-Inputs!$C$18)+Inputs!$C$21*Inputs!$C$18-Inputs!$C$22-F$4/(1+F$4)*Inputs!$C$23)*(1+Inputs!$C$24)/($B$10-Inputs!$C$24)/(1+$B$10)^5-Inputs!$C$36,0) | G10: =ROUND(Inputs!$C$5*(1+G$4)^1*(Inputs!$C$30*(1-Inputs!$C$18)+Inputs!$C$21*Inputs!$C$18-Inputs!$C$22-G$4/(1+G$4)*Inputs!$C$23)/(1+$B$10)^1+Inputs!$C$5*(1+G$4)^2*(Inputs!$C$31*(1-Inputs!$C$18)+Inputs!$C$21*Inputs!$C$18-Inputs!$C$22-G$4/(1+G$4)*Inputs!$C$23)/(1+$B$10)^2+Inputs!$C$5*(1+G$4)^3*(Inputs!$C$31*(1-Inputs!$C$18)+Inputs!$C$21*Inputs!$C$18-Inputs!$C$22-G$4/(1+G$4)*Inputs!$C$23)/(1+$B$10)^3+Inputs!$C$5*(1+G$4)^4*(Inputs!$C$31*(1-Inputs!$C$18)+Inputs!$C$21*Inputs!$C$18-Inputs!$C$22-G$4/(1+G$4)*Inputs!$C$23)/(1+$B$10)^4+Inputs!$C$5*(1+G$4)^5*(Inputs!$C$31*(1-Inputs!$C$18)+Inputs!$C$21*Inputs!$C$18-Inputs!$C$22-G$4/(1+G$4)*Inputs!$C$23)/(1+$B$10)^5+Inputs!$C$5*(1+G$4)^5*(Inputs!$C$31*(1-Inputs!$C$18)+Inputs!$C$21*Inputs!$C$18-Inputs!$C$22-G$4/(1+G$4)*Inputs!$C$23)*(1+Inputs!$C$24)/($B$10-Inputs!$C$24)/(1+$B$10)^5-Inputs!$C$36,0) | H10: =ROUND(Inputs!$C$5*(1+H$4)^1*(Inputs!$C$30*(1-Inputs!$C$18)+Inputs!$C$21*Inputs!$C$18-Inputs!$C$22-H$4/(1+H$4)*Inputs!$C$23)/(1+$B$10)^1+Inputs!$C$5*(1+H$4)^2*(Inputs!$C$31*(1-Inputs!$C$18)+Inputs!$C$21*Inputs!$C$18-Inputs!$C$22-H$4/(1+H$4)*Inputs!$C$23)/(1+$B$10)^2+Inputs!$C$5*(1+H$4)^3*(Inputs!$C$31*(1-Inputs!$C$18)+Inputs!$C$21*Inputs!$C$18-Inputs!$C$22-H$4/(1+H$4)*Inputs!$C$23)/(1+$B$10)^3+Inputs!$C$5*(1+H$4)^4*(Inputs!$C$31*(1-Inputs!$C$18)+Inputs!$C$21*Inputs!$C$18-Inputs!$C$22-H$4/(1+H$4)*Inputs!$C$23)/(1+$B$10)^4+Inputs!$C$5*(1+H$4)^5*(Inputs!$C$31*(1-Inputs!$C$18)+Inputs!$C$21*Inputs!$C$18-Inputs!$C$22-H$4/(1+H$4)*Inputs!$C$23)/(1+$B$10)^5+Inputs!$C$5*(1+H$4)^5*(Inputs!$C$31*(1-Inputs!$C$18)+Inputs!$C$21*Inputs!$C$18-Inputs!$C$22-H$4/(1+H$4)*Inputs!$C$23)*(1+Inputs!$C$24)/($B$10-Inputs!$C$24)/(1+$B$10)^5-Inputs!$C$36,0) | I10: =ROUND(Inputs!$C$5*(1+I$4)^1*(Inputs!$C$30*(1-Inputs!$C$18)+Inputs!$C$21*Inputs!$C$18-Inputs!$C$22-I$4/(1+I$4)*Inputs!$C$23)/(1+$B$10)^1+Inputs!$C$5*(1+I$4)^2*(Inputs!$C$31*(1-Inputs!$C$18)+Inputs!$C$21*Inputs!$C$18-Inputs!$C$22-I$4/(1+I$4)*Inputs!$C$23)/(1+$B$10)^2+Inputs!$C$5*(1+I$4)^3*(Inputs!$C$31*(1-Inputs!$C$18)+Inputs!$C$21*Inputs!$C$18-Inputs!$C$22-I$4/(1+I$4)*Inputs!$C$23)/(1+$B$10)^3+Inputs!$C$5*(1+I$4)^4*(Inputs!$C$31*(1-Inputs!$C$18)+Inputs!$C$21*Inputs!$C$18-Inputs!$C$22-I$4/(1+I$4)*Inputs!$C$23)/(1+$B$10)^4+Inputs!$C$5*(1+I$4)^5*(Inputs!$C$31*(1-Inputs!$C$18)+Inputs!$C$21*Inputs!$C$18-Inputs!$C$22-I$4/(1+I$4)*Inputs!$C$23)/(1+$B$10)^5+Inputs!$C$5*(1+I$4)^5*(Inputs!$C$31*(1-Inputs!$C$18)+Inputs!$C$21*Inputs!$C$18-Inputs!$C$22-I$4/(1+I$4)*Inputs!$C$23)*(1+Inputs!$C$24)/($B$10-Inputs!$C$24)/(1+$B$10)^5-Inputs!$C$36,0)
B11: Gold = Base Case (WACC 6.82%, Growth 8%)

Sheet Valuation
B1: VALUATION SUMMARY - BioFresh SAS
B3: Method | C3: Implied EV (€k) | D3: vs. Offer Price
B4: DCF - Bear Scenario | C4: =Scenarios!$C$22 | D4: =Scenarios!$C$22/Inputs!$C$36-1 | E4: 3% growth, 13.0% margins - conservative
B5: DCF - Base Scenario | C5: =Scenarios!$C$52 | D5: =Scenarios!$C$52/Inputs!$C$36-1 | E5: 8% growth, 14.5-15.0% margins - base
B6: DCF - Bull Scenario | C6: =Scenarios!$C$82 | D6: =Scenarios!$C$82/Inputs!$C$36-1 | E6: 12% growth, 15.5% margins - optimistic
B7: Entry EV (Offer Price) | C7: =Inputs!$C$36 | D7: =0 | E7: Verdant Capital NBO
B10: Bear DCF | C10: 84058
B11: Base DCF | C11: 119945
B12: Bull DCF | C12: 144154
B13: Entry EV | C13: 75000
B30: CONCLUSION & INVESTMENT RECOMMENDATION
B31: The DCF produces the highest implied enterprise value €88M–€144M depending on scenario because it capitalises future growth. At an 8% revenue CAGR and margin expansion to 15%, BioFresh generates over €5.8M of unlevered free cash flow by FY2029. The terminal value alone accounts for approximately 83% of total DCF value meaning the model is acutely sensitive to the long-term growth and WACC assumptions.
B32: The offer price of €75M sits deliberately between these two bounds. Verdant pays a 31% control premium over the trading-comps median €57M compensating the founders for relinquishing ownership. At the same time, Verdant acquires the asset at a 37% discount to the base-case DCF value capturing substantial upside. This is the fundamental of private equity buy below intrinsic value, apply operational improvements, exit at a higher multiple.
B33: NPV ANALYSIS & RECOMMENDATION
B34: The acquisition NPV is positive in all three scenarios- +€13M (Bear), +€45M (Base), +€69M (Bull). Even in the conservative bear case 3% revenue growth, compressed 13% EBITDA margin, the deal generates positive value for Verdant. The LBO generates an IRR of 16.2% in the bear case below the 20% hurdle but manageable, 26.7% in base case above hurdle which investment committee requirement mets and 33.3% in the bull case.
